<?xml version="1.0"?>
<!-- Day 19 - A differential-drive robot. Spawn into a world, bridge /cmd_vel, and drive. -->
<sdf version="1.8">
  <model name="diff_bot">
    <pose>0 0 0.1 0 0 0</pose>

    <!-- chassis -->
    <link name="base_link">
      <inertial>
        <mass>5.0</mass>
        <inertia><ixx>0.1</ixx><iyy>0.1</iyy><izz>0.1</izz>
                 <ixy>0</ixy><ixz>0</ixz><iyz>0</iyz></inertia>
      </inertial>
      <visual name="v">
        <geometry><box><size>0.4 0.3 0.1</size></box></geometry>
        <material><ambient>0.2 0.4 0.8 1</ambient></material>
      </visual>
      <collision name="c">
        <geometry><box><size>0.4 0.3 0.1</size></box></geometry>
      </collision>
    </link>

    <!-- left wheel -->
    <link name="left_wheel">
      <pose>0 0.18 0 -1.5708 0 0</pose>
      <inertial><mass>0.5</mass>
        <inertia><ixx>0.001</ixx><iyy>0.001</iyy><izz>0.001</izz>
                 <ixy>0</ixy><ixz>0</ixz><iyz>0</iyz></inertia></inertial>
      <visual name="v"><geometry><cylinder><radius>0.1</radius><length>0.05</length></cylinder></geometry></visual>
      <collision name="c"><geometry><cylinder><radius>0.1</radius><length>0.05</length></cylinder></geometry></collision>
    </link>
    <joint name="left_wheel_joint" type="revolute">
      <parent>base_link</parent><child>left_wheel</child>
      <axis><xyz>0 1 0</xyz><limit><lower>-1e16</lower><upper>1e16</upper></limit></axis>
    </joint>

    <!-- right wheel -->
    <link name="right_wheel">
      <pose>0 -0.18 0 -1.5708 0 0</pose>
      <inertial><mass>0.5</mass>
        <inertia><ixx>0.001</ixx><iyy>0.001</iyy><izz>0.001</izz>
                 <ixy>0</ixy><ixz>0</ixz><iyz>0</iyz></inertia></inertial>
      <visual name="v"><geometry><cylinder><radius>0.1</radius><length>0.05</length></cylinder></geometry></visual>
      <collision name="c"><geometry><cylinder><radius>0.1</radius><length>0.05</length></cylinder></geometry></collision>
    </link>
    <joint name="right_wheel_joint" type="revolute">
      <parent>base_link</parent><child>right_wheel</child>
      <axis><xyz>0 1 0</xyz><limit><lower>-1e16</lower><upper>1e16</upper></limit></axis>
    </joint>

    <!-- caster (free-rolling sphere) -->
    <link name="caster">
      <pose>0.15 0 -0.05 0 0 0</pose>
      <inertial><mass>0.1</mass>
        <inertia><ixx>0.0001</ixx><iyy>0.0001</iyy><izz>0.0001</izz>
                 <ixy>0</ixy><ixz>0</ixz><iyz>0</iyz></inertia></inertial>
      <visual name="v"><geometry><sphere><radius>0.05</radius></sphere></geometry></visual>
      <collision name="c"><geometry><sphere><radius>0.05</radius></sphere></geometry></collision>
    </link>
    <joint name="caster_joint" type="ball">
      <parent>base_link</parent><child>caster</child>
    </joint>

    <!-- diff-drive plugin: listens on cmd_vel -->
    <plugin filename="gz-sim-diff-drive-system" name="gz::sim::systems::DiffDrive">
      <left_joint>left_wheel_joint</left_joint>
      <right_joint>right_wheel_joint</right_joint>
      <wheel_separation>0.36</wheel_separation>
      <wheel_radius>0.1</wheel_radius>
      <topic>cmd_vel</topic>
      <odom_topic>odom</odom_topic>
    </plugin>
  </model>
</sdf>
