<mujoco model="cartpole">
  <option gravity="0 0 -9.81" timestep="0.01"/>
  <worldbody>
    <light pos="0 0 3"/>
    <geom type="plane" size="5 5 0.1" rgba="0.8 0.9 0.8 1"/>

    <body name="cart" pos="0 0 0.5">
      <joint name="slider" type="slide" axis="1 0 0"/>
      <geom type="box" size="0.2 0.15 0.1" rgba="0.2 0.4 0.9 1"/>
      <body name="pole" pos="0 0 0.1">
        <joint name="hinge" type="hinge" axis="0 1 0"/>
        <geom type="capsule" fromto="0 0 0  0 0 0.6" size="0.04" rgba="0.9 0.4 0.2 1"/>
      </body>
    </body>
  </worldbody>
  <actuator>
    <motor name="cart_motor" joint="slider" gear="50" ctrlrange="-1 1"/>
  </actuator>
</mujoco>
