<mujoco model="two_link_arm">
  <option gravity="0 0 -9.81" timestep="0.002"/>

  <worldbody>
    <light pos="0 0 3"/>
    <geom name="floor" type="plane" size="3 3 0.1" rgba="0.8 0.9 0.8 1"/>

    <body name="upper_arm" pos="0 0 1">
      <joint name="shoulder" type="hinge" axis="0 1 0"/>
      <geom type="capsule" fromto="0 0 0  0.5 0 0" size="0.05" rgba="0.2 0.4 0.9 1"/>

      <body name="forearm" pos="0.5 0 0">
        <joint name="elbow" type="hinge" axis="0 1 0"/>
        <geom type="capsule" fromto="0 0 0  0.4 0 0" size="0.04" rgba="0.9 0.4 0.2 1"/>
      </body>
    </body>
  </worldbody>

  <actuator>
    <position name="shoulder_pos" joint="shoulder" kp="100"/>
    <position name="elbow_pos"    joint="elbow"    kp="100"/>
  </actuator>
</mujoco>
